<?xml version="1.0" ?>
<!-- =================================================================================== -->
<!-- |    This document was autogenerated by xacro from rrbot.xacro                    | -->
<!-- |    EDITING THIS FILE BY HAND IS NOT RECOMMENDED                                 | -->
<!-- =================================================================================== -->
<robot name="rrbot" xmlns:xacro="http://www.ros.org/wiki/xacro">
  <!-- Link4 -->
  <!--xacro:property name="model_wrist1" value="package://rrbot_description/meshes/hand/wrist1.dae" />
  <xacro:property name="model_wrist2" value="package://rrbot_description/meshes/hand/wrist2.dae" />
  <xacro:property name="model_palm" value="package://rrbot_description/meshes/hand/palm.dae" /-->
  <!-- ros_control plugin -->
  <gazebo>
    <plugin filename="libgazebo_ros_control.so" name="gazebo_ros_control">
      <robotNamespace>/rrbot</robotNamespace>
      <robotSimType>gazebo_ros_control/DefaultRobotHWSim</robotSimType>
    </plugin>
    <!--plugin name="gazebo_mimic_control" filename="libroboticsgroup_gazebo_mimic_joint_plugin.so"/-->
  </gazebo>
  <!-- Link1 -->
  <gazebo reference="link1">
    <material>Gazebo/White</material>
  </gazebo>
  <gazebo reference="link_bridge">
    <material>Gazebo/White</material>
  </gazebo>
  <!-- Link2 -->
  <gazebo reference="link2">
    <material>Gazebo/Grey</material>
  </gazebo>
  <!-- Link3 -->
  <gazebo reference="link3">
    <material>Gazebo/Grey</material>
  </gazebo>
  <!-- Link4 -->
  <gazebo reference="link4">
    <material>Gazebo/Grey</material>
  </gazebo>
  <gazebo reference="wrist_link1">
    <material>Gazebo/Grey</material>
  </gazebo>
  <gazebo reference="wrist_link2">
    <material>Gazebo/Grey</material>
  </gazebo>
  <gazebo reference="palm">
    <material>Gazebo/Grey</material>
  </gazebo>
  <!--gazebo reference="wrist_joint1" mimicJoint="wrist_joint2"/-->
  <material name="black">
    <color rgba="0.0 0.0 0.0 1.0"/>
  </material>
  <material name="blue">
    <color rgba="0.0 0.0 0.8 1.0"/>
  </material>
  <material name="green">
    <color rgba="0.0 0.8 0.0 1.0"/>
  </material>
  <material name="grey">
    <color rgba="0.2 0.2 0.2 1.0"/>
  </material>
  <material name="orange">
    <color rgba="1.0 0.423529411765 0.0392156862745 1.0"/>
  </material>
  <material name="brown">
    <color rgba="0.870588235294 0.811764705882 0.764705882353 1.0"/>
  </material>
  <material name="red">
    <color rgba="0.8 0.0 0.0 1.0"/>
  </material>
  <material name="white">
    <color rgba="1.0 1.0 1.0 1.0"/>
  </material>
  <!-- Used for fixing robot to Gazebo 'base_link' -->
  <link name="world"/>
  <joint name="fixed" type="fixed">
    <parent link="world"/>
    <child link="link1"/>
  </joint>
  <!-- Base Link -->
  <link name="link1">
    <collision>
      <origin rpy="0 0 0" xyz="0 0 0.75"/>
      <geometry>
        <box size="0.05 0.05 1.5"/>
      </geometry>
    </collision>
    <visual>
      <origin rpy="0 0 0" xyz="0 0 0.75"/>
      <geometry>
        <box size="0.05 0.05 1.5"/>
      </geometry>
      <material name="orange"/>
    </visual>
    <inertial>
      <origin rpy="0 0 0" xyz="0 0 0.75"/>
      <mass value="2.0"/>
      <inertia ixx="4.505" ixy="0.0" ixz="0.0" iyy="4.505" iyz="0.0" izz="0.01"/>
    </inertial>
  </link>
  <joint name="joint_bridge" type="fixed">
    <parent link="link1"/>
    <child link="link_bridge"/>
    <origin rpy="0 0 0" xyz="0 0.05 1.475"/>
    <axis xyz="0 1 0"/>
    <dynamics damping="0.7"/>
  </joint>
  <link name="link_bridge">
    <collision>
      <origin rpy="0 0 0" xyz="0 0.075 0"/>
      <geometry>
        <box size="0.05 0.15 0.05"/>
      </geometry>
    </collision>
    <visual>
      <origin rpy="0 0 0" xyz="0 0.05 0"/>
      <geometry>
        <box size="0.05 0.15 0.05"/>
      </geometry>
      <material name="orange"/>
    </visual>
    <inertial>
      <origin rpy="0 0 0" xyz="0 0.05 0"/>
      <mass value="2.0"/>
      <inertia ixx="0.01" ixy="0.0" ixz="0.0" iyy="0.01" iyz="0.0" izz="0.01"/>
    </inertial>
  </link>
  <joint name="joint1" type="continuous">
    <parent link="link_bridge"/>
    <child link="link2"/>
    <origin rpy="0 0 0" xyz="0 0.15 -0.05"/>
    <axis xyz="0 1 0"/>
    <dynamics damping="0.7"/>
  </joint>
  <!-- Middle Link -->
  <link name="link2">
    <collision>
      <origin rpy="0 0 0" xyz="0 0 0.125"/>
      <geometry>
        <!--box size="${width} ${width} ${height2}"/-->
        <mesh filename="package://rrbot_description/meshes/humerus_0.1_r.dae" scale="0.6 0.6 0.6"/>
      </geometry>
    </collision>
    <visual>
      <origin rpy="0 0 0" xyz="0 0 0.125"/>
      <geometry>
        <!--box size="${width} ${width} ${height2}"/-->
        <mesh filename="package://rrbot_description/meshes/humerus_0.1_r.dae" scale="0.6 0.6 0.6"/>
      </geometry>
      <!--material name="black"/-->
    </visual>
    <inertial>
      <origin rpy="0 0 0" xyz="0 0 0.125"/>
      <mass value="2.0"/>
      <inertia ixx="0.13" ixy="0.0" ixz="0.0" iyy="0.13" iyz="0.0" izz="0.01"/>
    </inertial>
  </link>
  <joint name="joint2" type="continuous">
    <parent link="link2"/>
    <child link="link3"/>
    <origin rpy="0 0 0" xyz="0.04 0 0.25"/>
    <axis xyz="0 1 0"/>
    <dynamics damping="0.7"/>
  </joint>
  <link name="link3">
    <collision>
      <origin rpy="0 0 0" xyz="0 0 0.2"/>
      <geometry>
        <!--box size="${width} ${width} ${height3}"/-->
        <mesh filename="package://rrbot_description/meshes/ulna_0.1_r.dae" scale="0.6 0.6 0.6"/>
      </geometry>
    </collision>
    <visual>
      <origin rpy="0 0 0" xyz="0 0 0.2"/>
      <geometry>
        <!--box size="${width} ${width} ${height3}"/-->
        <mesh filename="package://rrbot_description/meshes/ulna_0.1_r.dae" scale="0.6 0.6 0.6"/>
      </geometry>
      <material name="orange"/>
    </visual>
    <inertial>
      <origin rpy="0 0 0" xyz="0 0 0.2"/>
      <mass value="2.0"/>
      <inertia ixx="0.325" ixy="0.0" ixz="0.0" iyy="0.325" iyz="0.0" izz="0.01"/>
    </inertial>
  </link>
  <joint name="joint3" type="continuous">
    <parent link="link3"/>
    <child link="link4"/>
    <origin rpy="0 0 0" xyz="-0.014 0.016 0.02"/>
    <axis xyz="0 -0.0380676253431 0.999275165258"/>
    <!--axis xyz="0 0 1" /-->
    <dynamics damping="0.7"/>
  </joint>
  <link name="link4">
    <collision>
      <origin rpy="0 0 0" xyz="0 0 0.2"/>
      <geometry>
        <!--box size="${width} ${width} ${height4}"/-->
        <mesh filename="package://rrbot_description/meshes/radius_0.1_t.dae" scale="0.6 0.6 0.6"/>
      </geometry>
    </collision>
    <visual>
      <origin rpy="0 0 0" xyz="0 0 0.2"/>
      <geometry>
        <!--box size="${width} ${width} ${height4}"/-->
        <mesh filename="package://rrbot_description/meshes/radius_0.1_t.dae" scale="0.6 0.6 0.6"/>
      </geometry>
      <material name="orange"/>
    </visual>
    <inertial>
      <origin rpy="0 0 0" xyz="0 0 0.2"/>
      <mass value="2.0"/>
      <inertia ixx="0.325" ixy="0.0" ixz="0.0" iyy="0.325" iyz="0.0" izz="0.01"/>
    </inertial>
  </link>
  <!--********************* WRIST *********************** -->
  <joint name="wrist_joint1" type="continuous">
    <parent link="link4"/>
    <child link="wrist_link1"/>
    <origin rpy="0 0 0" xyz="0 0 0.41"/>
    <axis xyz="0 1 0"/>
    <dynamics damping="0.7"/>
  </joint>
  <link name="wrist_link1">
    <collision>
      <origin rpy="0 0 0" xyz="0 0 0.02"/>
      <geometry>
        <box size="0.02 0.08 0.04"/>
        <!--mesh filename="${model_wrist1}" scale="${model_scale}" /-->
      </geometry>
    </collision>
    <visual>
      <origin rpy="0 0 0" xyz="0 0 0.02"/>
      <geometry>
        <box size="0.02 0.08 0.04"/>
        <!--mesh filename="${model_wrist1}" scale="${model_scale}" /-->
      </geometry>
      <material name="orange"/>
    </visual>
    <inertial>
      <origin rpy="0 0 0" xyz="0 0 0.02"/>
      <mass value="1"/>
      <inertia ixx="0.002" ixy="0.0" ixz="0.0" iyy="0.002" iyz="0.0" izz="0.0008"/>
    </inertial>
  </link>
  <joint name="wrist_joint2" type="continuous">
    <parent link="wrist_link1"/>
    <child link="wrist_link2"/>
    <origin rpy="0 0 0" xyz="0 0 0.05"/>
    <axis xyz="0 1 0"/>
    <dynamics damping="0.7"/>
    <mimic joint="wrist_joint1" multiplier="1" offset="0"/>
  </joint>
  <link name="wrist_link2">
    <collision>
      <origin rpy="0 0 0" xyz="0 0 0.02"/>
      <geometry>
        <box size="0.02 0.08 0.04"/>
        <!--mesh filename="${model_wrist2}" scale="${model_scale}" /-->
      </geometry>
    </collision>
    <visual>
      <origin rpy="0 0 0" xyz="0 0 0.02"/>
      <geometry>
        <box size="0.02 0.08 0.04"/>
        <!--mesh filename="${model_wrist2}" scale="${model_scale}" /-->
      </geometry>
      <material name="orange"/>
    </visual>
    <inertial>
      <origin rpy="0 0 0" xyz="0 0 0.02"/>
      <mass value="1"/>
      <inertia ixx="0.002" ixy="0.0" ixz="0.0" iyy="0.002" iyz="0.0" izz="0.0008"/>
    </inertial>
  </link>
  <joint name="wrist_connector" type="fixed">
    <parent link="wrist_link2"/>
    <child link="palm"/>
    <origin rpy="0 0 0" xyz="0 0 0.04"/>
  </joint>
  <!--**************** Palm ********************-->
  <link name="palm">
    <collision>
      <origin rpy="0 0 0" xyz="0 0 0.05"/>
      <geometry>
        <box size="0.025 0.09 0.1"/>
        <!--mesh filename="${model_radius}" scale="${model_scale}" /-->
      </geometry>
    </collision>
    <visual>
      <origin rpy="0 0 0" xyz="0 0 0.05"/>
      <geometry>
        <box size="0.025 0.09 0.1"/>
        <!--mesh filename="${model_hand}" scale="${model_scale}" /-->
      </geometry>
      <material name="orange"/>
    </visual>
    <inertial>
      <origin rpy="0 0 0" xyz="0 0 0.05"/>
      <mass value="2.0"/>
      <inertia ixx="0.1086" ixy="0.0" ixz="0.0" iyy="0.075" iyz="0.0" izz="0.0636"/>
    </inertial>
  </link>
  <!--******************* THUMB **********************-->
  <joint name="thumb_joint1" type="continuous">
    <parent link="palm"/>
    <child link="thumb_link1"/>
    <origin rpy="-0.785398163397 0 0" xyz="0 0.055 0.02"/>
    <axis xyz="0 1 0"/>
    <dynamics damping="0.7"/>
  </joint>
  <link name="thumb_link1">
    <collision>
      <origin rpy="0 0 0" xyz="0 0 0.02"/>
      <geometry>
        <box size="0.02 0.02 0.04"/>
      </geometry>
    </collision>
    <visual>
      <origin rpy="0 0 0" xyz="0 0 0.02"/>
      <geometry>
        <box size="0.02 0.02 0.04"/>
      </geometry>
      <material name="orange"/>
    </visual>
    <inertial>
      <origin rpy="0 0 0" xyz="0 0 0.02"/>
      <mass value="1"/>
      <inertia ixx="0.002" ixy="0.0" ixz="0.0" iyy="0.002" iyz="0.0" izz="0.0008"/>
    </inertial>
  </link>
  <joint name="thumb_joint2" type="continuous">
    <parent link="thumb_link1"/>
    <child link="thumb_link2"/>
    <origin rpy="0 0 0" xyz="0 0 0.05"/>
    <axis xyz="0 1 0"/>
    <dynamics damping="0.7"/>
    <mimic joint="thumb_joint1" multiplier="1" offset="0"/>
  </joint>
  <link name="thumb_link2">
    <collision>
      <origin rpy="0 0 0" xyz="0 0 0.02"/>
      <geometry>
        <box size="0.02 0.02 0.04"/>
      </geometry>
    </collision>
    <visual>
      <origin rpy="0 0 0" xyz="0 0 0.02"/>
      <geometry>
        <box size="0.02 0.02 0.04"/>
      </geometry>
      <material name="orange"/>
    </visual>
    <inertial>
      <origin rpy="0 0 0" xyz="0 0 0.02"/>
      <mass value="1"/>
      <inertia ixx="0.002" ixy="0.0" ixz="0.0" iyy="0.002" iyz="0.0" izz="0.0008"/>
    </inertial>
  </link>
  <joint name="thumb_joint3" type="continuous">
    <parent link="thumb_link2"/>
    <child link="thumb_link3"/>
    <origin rpy="0 0 0" xyz="0 0 0.05"/>
    <axis xyz="0 1 0"/>
    <dynamics damping="0.7"/>
    <mimic joint="thumb_joint1" multiplier="1" offset="0"/>
  </joint>
  <link name="thumb_link3">
    <collision>
      <origin rpy="0 0 0" xyz="0 0 0.02"/>
      <geometry>
        <box size="0.02 0.02 0.04"/>
      </geometry>
    </collision>
    <visual>
      <origin rpy="0 0 0" xyz="0 0 0.02"/>
      <geometry>
        <box size="0.02 0.02 0.04"/>
      </geometry>
      <material name="orange"/>
    </visual>
    <inertial>
      <origin rpy="0 0 0" xyz="0 0 0.02"/>
      <mass value="1"/>
      <inertia ixx="0.002" ixy="0.0" ixz="0.0" iyy="0.002" iyz="0.0" izz="0.0008"/>
    </inertial>
  </link>
  <!--***************** INDEX *********************-->
  <joint name="index_joint1" type="continuous">
    <parent link="palm"/>
    <child link="index_link1"/>
    <origin rpy="-0.10471975512 0 0" xyz="0 0.045 0.11"/>
    <axis xyz="0 1 0"/>
    <dynamics damping="0.7"/>
  </joint>
  <link name="index_link1">
    <collision>
      <origin rpy="0 0 0" xyz="0 0 0.02"/>
      <geometry>
        <box size="0.02 0.02 0.04"/>
      </geometry>
    </collision>
    <visual>
      <origin rpy="0 0 0" xyz="0 0 0.02"/>
      <geometry>
        <box size="0.02 0.02 0.04"/>
      </geometry>
      <material name="orange"/>
    </visual>
    <inertial>
      <origin rpy="0 0 0" xyz="0 0 0.02"/>
      <mass value="1"/>
      <inertia ixx="0.002" ixy="0.0" ixz="0.0" iyy="0.002" iyz="0.0" izz="0.0008"/>
    </inertial>
  </link>
  <joint name="index_joint2" type="continuous">
    <parent link="index_link1"/>
    <child link="index_link2"/>
    <origin rpy="0 0 0" xyz="0 0 0.05"/>
    <axis xyz="0 1 0"/>
    <dynamics damping="0.7"/>
    <mimic joint="index_joint1" multiplier="1" offset="0"/>
  </joint>
  <link name="index_link2">
    <collision>
      <origin rpy="0 0 0" xyz="0 0 0.02"/>
      <geometry>
        <box size="0.02 0.02 0.04"/>
      </geometry>
    </collision>
    <visual>
      <origin rpy="0 0 0" xyz="0 0 0.02"/>
      <geometry>
        <box size="0.02 0.02 0.04"/>
      </geometry>
      <material name="orange"/>
    </visual>
    <inertial>
      <origin rpy="0 0 0" xyz="0 0 0.02"/>
      <mass value="1"/>
      <inertia ixx="0.002" ixy="0.0" ixz="0.0" iyy="0.002" iyz="0.0" izz="0.0008"/>
    </inertial>
  </link>
  <joint name="index_joint3" type="continuous">
    <parent link="index_link2"/>
    <child link="index_link3"/>
    <origin rpy="0 0 0" xyz="0 0 0.05"/>
    <axis xyz="0 1 0"/>
    <dynamics damping="0.7"/>
    <mimic joint="index_joint1" multiplier="1" offset="0"/>
  </joint>
  <link name="index_link3">
    <collision>
      <origin rpy="0 0 0" xyz="0 0 0.02"/>
      <geometry>
        <box size="0.02 0.02 0.04"/>
      </geometry>
    </collision>
    <visual>
      <origin rpy="0 0 0" xyz="0 0 0.02"/>
      <geometry>
        <box size="0.02 0.02 0.04"/>
      </geometry>
      <material name="orange"/>
    </visual>
    <inertial>
      <origin rpy="0 0 0" xyz="0 0 0.02"/>
      <mass value="1"/>
      <inertia ixx="0.002" ixy="0.0" ixz="0.0" iyy="0.002" iyz="0.0" izz="0.0008"/>
    </inertial>
  </link>
  <!--***************** MIDDLE *********************-->
  <joint name="middle_joint1" type="continuous">
    <parent link="palm"/>
    <child link="middle_link1"/>
    <origin rpy="0 0 0" xyz="0 0.015 0.11"/>
    <axis xyz="0 1 0"/>
    <dynamics damping="0.7"/>
  </joint>
  <link name="middle_link1">
    <collision>
      <origin rpy="0 0 0" xyz="0 0 0.02"/>
      <geometry>
        <box size="0.02 0.02 0.04"/>
      </geometry>
    </collision>
    <visual>
      <origin rpy="0 0 0" xyz="0 0 0.02"/>
      <geometry>
        <box size="0.02 0.02 0.04"/>
      </geometry>
      <material name="orange"/>
    </visual>
    <inertial>
      <origin rpy="0 0 0" xyz="0 0 0.02"/>
      <mass value="1"/>
      <inertia ixx="0.002" ixy="0.0" ixz="0.0" iyy="0.002" iyz="0.0" izz="0.0008"/>
    </inertial>
  </link>
  <joint name="middle_joint2" type="continuous">
    <parent link="middle_link1"/>
    <child link="middle_link2"/>
    <origin rpy="0 0 0" xyz="0 0 0.05"/>
    <axis xyz="0 1 0"/>
    <dynamics damping="0.7"/>
    <mimic joint="middle_joint1" multiplier="1" offset="0"/>
  </joint>
  <link name="middle_link2">
    <collision>
      <origin rpy="0 0 0" xyz="0 0 0.02"/>
      <geometry>
        <box size="0.02 0.02 0.04"/>
      </geometry>
    </collision>
    <visual>
      <origin rpy="0 0 0" xyz="0 0 0.02"/>
      <geometry>
        <box size="0.02 0.02 0.04"/>
      </geometry>
      <material name="orange"/>
    </visual>
    <inertial>
      <origin rpy="0 0 0" xyz="0 0 0.02"/>
      <mass value="1"/>
      <inertia ixx="0.002" ixy="0.0" ixz="0.0" iyy="0.002" iyz="0.0" izz="0.0008"/>
    </inertial>
  </link>
  <joint name="middle_joint3" type="continuous">
    <parent link="middle_link2"/>
    <child link="middle_link3"/>
    <origin rpy="0 0 0" xyz="0 0 0.05"/>
    <axis xyz="0 1 0"/>
    <dynamics damping="0.7"/>
    <mimic joint="middle_joint1" multiplier="1" offset="0"/>
  </joint>
  <link name="middle_link3">
    <collision>
      <origin rpy="0 0 0" xyz="0 0 0.02"/>
      <geometry>
        <box size="0.02 0.02 0.04"/>
      </geometry>
    </collision>
    <visual>
      <origin rpy="0 0 0" xyz="0 0 0.02"/>
      <geometry>
        <box size="0.02 0.02 0.04"/>
      </geometry>
      <material name="orange"/>
    </visual>
    <inertial>
      <origin rpy="0 0 0" xyz="0 0 0.02"/>
      <mass value="1"/>
      <inertia ixx="0.002" ixy="0.0" ixz="0.0" iyy="0.002" iyz="0.0" izz="0.0008"/>
    </inertial>
  </link>
  <!--***************** SMALL *********************-->
  <joint name="small_joint1" type="continuous">
    <parent link="palm"/>
    <child link="small_link1"/>
    <origin rpy="0.0523598775598 0 0" xyz="0 -0.015 0.11"/>
    <axis xyz="0 1 0"/>
    <dynamics damping="0.7"/>
  </joint>
  <link name="small_link1">
    <collision>
      <origin rpy="0 0 0" xyz="0 0 0.02"/>
      <geometry>
        <box size="0.02 0.02 0.04"/>
      </geometry>
    </collision>
    <visual>
      <origin rpy="0 0 0" xyz="0 0 0.02"/>
      <geometry>
        <box size="0.02 0.02 0.04"/>
      </geometry>
      <material name="orange"/>
    </visual>
    <inertial>
      <origin rpy="0 0 0" xyz="0 0 0.02"/>
      <mass value="1"/>
      <inertia ixx="0.002" ixy="0.0" ixz="0.0" iyy="0.002" iyz="0.0" izz="0.0008"/>
    </inertial>
  </link>
  <joint name="small_joint2" type="continuous">
    <parent link="small_link1"/>
    <child link="small_link2"/>
    <origin rpy="0 0 0" xyz="0 0 0.05"/>
    <axis xyz="0 1 0"/>
    <dynamics damping="0.7"/>
    <mimic joint="small_joint1" multiplier="1" offset="0"/>
  </joint>
  <link name="small_link2">
    <collision>
      <origin rpy="0 0 0" xyz="0 0 0.02"/>
      <geometry>
        <box size="0.02 0.02 0.04"/>
      </geometry>
    </collision>
    <visual>
      <origin rpy="0 0 0" xyz="0 0 0.02"/>
      <geometry>
        <box size="0.02 0.02 0.04"/>
      </geometry>
      <material name="orange"/>
    </visual>
    <inertial>
      <origin rpy="0 0 0" xyz="0 0 0.02"/>
      <mass value="1"/>
      <inertia ixx="0.002" ixy="0.0" ixz="0.0" iyy="0.002" iyz="0.0" izz="0.0008"/>
    </inertial>
  </link>
  <joint name="small_joint3" type="continuous">
    <parent link="small_link2"/>
    <child link="small_link3"/>
    <origin rpy="0 0 0" xyz="0 0 0.05"/>
    <axis xyz="0 1 0"/>
    <dynamics damping="0.7"/>
    <mimic joint="small_joint1" multiplier="1" offset="0"/>
  </joint>
  <link name="small_link3">
    <collision>
      <origin rpy="0 0 0" xyz="0 0 0.02"/>
      <geometry>
        <box size="0.02 0.02 0.04"/>
      </geometry>
    </collision>
    <visual>
      <origin rpy="0 0 0" xyz="0 0 0.02"/>
      <geometry>
        <box size="0.02 0.02 0.04"/>
      </geometry>
      <material name="orange"/>
    </visual>
    <inertial>
      <origin rpy="0 0 0" xyz="0 0 0.02"/>
      <mass value="1"/>
      <inertia ixx="0.002" ixy="0.0" ixz="0.0" iyy="0.002" iyz="0.0" izz="0.0008"/>
    </inertial>
  </link>
  <!--***************** LITTLE *********************-->
  <joint name="little_joint1" type="continuous">
    <parent link="palm"/>
    <child link="little_link1"/>
    <origin rpy="0.10471975512 0 0" xyz="0 -0.045 0.11"/>
    <axis xyz="0 1 0"/>
    <dynamics damping="0.7"/>
  </joint>
  <link name="little_link1">
    <collision>
      <origin rpy="0 0 0" xyz="0 0 0.02"/>
      <geometry>
        <box size="0.02 0.02 0.04"/>
      </geometry>
    </collision>
    <visual>
      <origin rpy="0 0 0" xyz="0 0 0.02"/>
      <geometry>
        <box size="0.02 0.02 0.04"/>
      </geometry>
      <material name="orange"/>
    </visual>
    <inertial>
      <origin rpy="0 0 0" xyz="0 0 0.02"/>
      <mass value="1"/>
      <inertia ixx="0.002" ixy="0.0" ixz="0.0" iyy="0.002" iyz="0.0" izz="0.0008"/>
    </inertial>
  </link>
  <joint name="little_joint2" type="continuous">
    <parent link="little_link1"/>
    <child link="little_link2"/>
    <origin rpy="0 0 0" xyz="0 0 0.05"/>
    <axis xyz="0 1 0"/>
    <dynamics damping="0.7"/>
    <mimic joint="little_joint1" multiplier="1" offset="0"/>
  </joint>
  <link name="little_link2">
    <collision>
      <origin rpy="0 0 0" xyz="0 0 0.02"/>
      <geometry>
        <box size="0.02 0.02 0.04"/>
      </geometry>
    </collision>
    <visual>
      <origin rpy="0 0 0" xyz="0 0 0.02"/>
      <geometry>
        <box size="0.02 0.02 0.04"/>
      </geometry>
      <material name="orange"/>
    </visual>
    <inertial>
      <origin rpy="0 0 0" xyz="0 0 0.02"/>
      <mass value="1"/>
      <inertia ixx="0.002" ixy="0.0" ixz="0.0" iyy="0.002" iyz="0.0" izz="0.0008"/>
    </inertial>
  </link>
  <joint name="little_joint3" type="continuous">
    <parent link="little_link2"/>
    <child link="little_link3"/>
    <origin rpy="0 0 0" xyz="0 0 0.05"/>
    <axis xyz="0 1 0"/>
    <dynamics damping="0.7"/>
    <mimic joint="little_joint1" multiplier="1" offset="0"/>
  </joint>
  <link name="little_link3">
    <collision>
      <origin rpy="0 0 0" xyz="0 0 0.02"/>
      <geometry>
        <box size="0.02 0.02 0.04"/>
      </geometry>
    </collision>
    <visual>
      <origin rpy="0 0 0" xyz="0 0 0.02"/>
      <geometry>
        <box size="0.02 0.02 0.04"/>
      </geometry>
      <material name="orange"/>
    </visual>
    <inertial>
      <origin rpy="0 0 0" xyz="0 0 0.02"/>
      <mass value="1"/>
      <inertia ixx="0.002" ixy="0.0" ixz="0.0" iyy="0.002" iyz="0.0" izz="0.0008"/>
    </inertial>
  </link>
  <transmission name="tran1">
    <type>transmission_interface/SimpleTransmission</type>
    <joint name="joint1">
      <hardwareInterface>EffortJointInterface</hardwareInterface>
    </joint>
    <actuator name="motor1">
      <hardwareInterface>EffortJointInterface</hardwareInterface>
      <mechanicalReduction>1</mechanicalReduction>
    </actuator>
  </transmission>
  <transmission name="tran2">
    <type>transmission_interface/SimpleTransmission</type>
    <joint name="joint2">
      <hardwareInterface>EffortJointInterface</hardwareInterface>
    </joint>
    <actuator name="motor2">
      <hardwareInterface>EffortJointInterface</hardwareInterface>
      <mechanicalReduction>1</mechanicalReduction>
    </actuator>
  </transmission>
  <transmission name="tran3">
    <type>transmission_interface/SimpleTransmission</type>
    <joint name="joint3">
      <hardwareInterface>EffortJointInterface</hardwareInterface>
    </joint>
    <actuator name="motor3">
      <hardwareInterface>EffortJointInterface</hardwareInterface>
      <mechanicalReduction>1</mechanicalReduction>
    </actuator>
  </transmission>
  <transmission name="tran_wrist1">
    <type>transmission_interface/SimpleTransmission</type>
    <joint name="wrist_joint1">
      <hardwareInterface>EffortJointInterface</hardwareInterface>
    </joint>
    <actuator name="wrist_joint1">
      <hardwareInterface>EffortJointInterface</hardwareInterface>
      <mechanicalReduction>1</mechanicalReduction>
    </actuator>
  </transmission>
  <transmission name="tran_wrist2">
    <type>transmission_interface/SimpleTransmission</type>
    <joint name="wrist_joint2">
      <hardwareInterface>EffortJointInterface</hardwareInterface>
    </joint>
    <actuator name="wrist_joint2">
      <hardwareInterface>EffortJointInterface</hardwareInterface>
      <mechanicalReduction>1</mechanicalReduction>
    </actuator>
  </transmission>
  <transmission name="tran_thumb1">
    <type>transmission_interface/SimpleTransmission</type>
    <joint name="thumb_joint1">
      <hardwareInterface>EffortJointInterface</hardwareInterface>
    </joint>
    <actuator name="thumb_joint1">
      <hardwareInterface>EffortJointInterface</hardwareInterface>
      <mechanicalReduction>1</mechanicalReduction>
    </actuator>
  </transmission>
  <transmission name="tran_thumb2">
    <type>transmission_interface/SimpleTransmission</type>
    <joint name="thumb_joint2">
      <hardwareInterface>EffortJointInterface</hardwareInterface>
    </joint>
    <actuator name="thumb_joint2">
      <hardwareInterface>EffortJointInterface</hardwareInterface>
      <mechanicalReduction>1</mechanicalReduction>
    </actuator>
  </transmission>
  <transmission name="tran_thumb3">
    <type>transmission_interface/SimpleTransmission</type>
    <joint name="thumb_joint3">
      <hardwareInterface>EffortJointInterface</hardwareInterface>
    </joint>
    <actuator name="thumb_joint3">
      <hardwareInterface>EffortJointInterface</hardwareInterface>
      <mechanicalReduction>1</mechanicalReduction>
    </actuator>
  </transmission>
  <transmission name="tran_index1">
    <type>transmission_interface/SimpleTransmission</type>
    <joint name="index_joint1">
      <hardwareInterface>EffortJointInterface</hardwareInterface>
    </joint>
    <actuator name="index_joint1">
      <hardwareInterface>EffortJointInterface</hardwareInterface>
      <mechanicalReduction>1</mechanicalReduction>
    </actuator>
  </transmission>
  <transmission name="tran_index2">
    <type>transmission_interface/SimpleTransmission</type>
    <joint name="index_joint2">
      <hardwareInterface>EffortJointInterface</hardwareInterface>
    </joint>
    <actuator name="index_joint2">
      <hardwareInterface>EffortJointInterface</hardwareInterface>
      <mechanicalReduction>1</mechanicalReduction>
    </actuator>
  </transmission>
  <transmission name="tran_index3">
    <type>transmission_interface/SimpleTransmission</type>
    <joint name="index_joint3">
      <hardwareInterface>EffortJointInterface</hardwareInterface>
    </joint>
    <actuator name="index_joint3">
      <hardwareInterface>EffortJointInterface</hardwareInterface>
      <mechanicalReduction>1</mechanicalReduction>
    </actuator>
  </transmission>
  <transmission name="tran_middle1">
    <type>transmission_interface/SimpleTransmission</type>
    <joint name="middle_joint1">
      <hardwareInterface>EffortJointInterface</hardwareInterface>
    </joint>
    <actuator name="middle_joint1">
      <hardwareInterface>EffortJointInterface</hardwareInterface>
      <mechanicalReduction>1</mechanicalReduction>
    </actuator>
  </transmission>
  <transmission name="tran_middle2">
    <type>transmission_interface/SimpleTransmission</type>
    <joint name="middle_joint2">
      <hardwareInterface>EffortJointInterface</hardwareInterface>
    </joint>
    <actuator name="middle_joint2">
      <hardwareInterface>EffortJointInterface</hardwareInterface>
      <mechanicalReduction>1</mechanicalReduction>
    </actuator>
  </transmission>
  <transmission name="tran_middle3">
    <type>transmission_interface/SimpleTransmission</type>
    <joint name="middle_joint3">
      <hardwareInterface>EffortJointInterface</hardwareInterface>
    </joint>
    <actuator name="middle_joint3">
      <hardwareInterface>EffortJointInterface</hardwareInterface>
      <mechanicalReduction>1</mechanicalReduction>
    </actuator>
  </transmission>
  <transmission name="tran_small1">
    <type>transmission_interface/SimpleTransmission</type>
    <joint name="small_joint1">
      <hardwareInterface>EffortJointInterface</hardwareInterface>
    </joint>
    <actuator name="small_joint1">
      <hardwareInterface>EffortJointInterface</hardwareInterface>
      <mechanicalReduction>1</mechanicalReduction>
    </actuator>
  </transmission>
  <transmission name="tran_small2">
    <type>transmission_interface/SimpleTransmission</type>
    <joint name="small_joint2">
      <hardwareInterface>EffortJointInterface</hardwareInterface>
    </joint>
    <actuator name="small_joint2">
      <hardwareInterface>EffortJointInterface</hardwareInterface>
      <mechanicalReduction>1</mechanicalReduction>
    </actuator>
  </transmission>
  <transmission name="tran_small3">
    <type>transmission_interface/SimpleTransmission</type>
    <joint name="small_joint3">
      <hardwareInterface>EffortJointInterface</hardwareInterface>
    </joint>
    <actuator name="small_joint3">
      <hardwareInterface>EffortJointInterface</hardwareInterface>
      <mechanicalReduction>1</mechanicalReduction>
    </actuator>
  </transmission>
  <transmission name="tran_little1">
    <type>transmission_interface/SimpleTransmission</type>
    <joint name="little_joint1">
      <hardwareInterface>EffortJointInterface</hardwareInterface>
    </joint>
    <actuator name="little_joint1">
      <hardwareInterface>EffortJointInterface</hardwareInterface>
      <mechanicalReduction>1</mechanicalReduction>
    </actuator>
  </transmission>
  <transmission name="tran_little2">
    <type>transmission_interface/SimpleTransmission</type>
    <joint name="little_joint2">
      <hardwareInterface>EffortJointInterface</hardwareInterface>
    </joint>
    <actuator name="little_joint2">
      <hardwareInterface>EffortJointInterface</hardwareInterface>
      <mechanicalReduction>1</mechanicalReduction>
    </actuator>
  </transmission>
  <transmission name="tran_little3">
    <type>transmission_interface/SimpleTransmission</type>
    <joint name="little_joint3">
      <hardwareInterface>EffortJointInterface</hardwareInterface>
    </joint>
    <actuator name="little_joint3">
      <hardwareInterface>EffortJointInterface</hardwareInterface>
      <mechanicalReduction>1</mechanicalReduction>
    </actuator>
  </transmission>
</robot>

